<?xml version="1.0" encoding="UTF-8"?>
<testng-results ignored="0" total="14" passed="10" failed="4" skipped="0">
  <reporter-output>
  </reporter-output>
  <suite started-at="2025-01-13T21:21:44 IST" name="Default suite" finished-at="2025-01-13T21:22:03 IST" duration-ms="19113">
    <groups>
    </groups>
    <test started-at="2025-01-13T21:21:44 IST" name="Default test" finished-at="2025-01-13T21:22:03 IST" duration-ms="19113">
      <class name="api.testcases.UserTest_Practice">
        <test-method is-config="true" signature="generateTestData()[pri:0, instance:api.testcases.UserTest_Practice@233795b6]" started-at="2025-01-13T21:21:44 IST" name="generateTestData" finished-at="2025-01-13T21:21:44 IST" duration-ms="516" status="PASS">
          <reporter-output>
          </reporter-output>
        </test-method> <!-- generateTestData -->
        <test-method signature="testCreateUser()[pri:1, instance:api.testcases.UserTest_Practice@233795b6]" started-at="2025-01-13T21:21:44 IST" name="testCreateUser" finished-at="2025-01-13T21:21:47 IST" duration-ms="2394" status="PASS">
          <reporter-output>
          </reporter-output>
        </test-method> <!-- testCreateUser -->
        <test-method signature="testCreateUsersWithArray()[pri:2, instance:api.testcases.UserTest_Practice@233795b6]" started-at="2025-01-13T21:21:47 IST" name="testCreateUsersWithArray" finished-at="2025-01-13T21:21:49 IST" duration-ms="2193" status="PASS">
          <reporter-output>
          </reporter-output>
        </test-method> <!-- testCreateUsersWithArray -->
        <test-method signature="testCreateUsersWithList()[pri:3, instance:api.testcases.UserTest_Practice@233795b6]" started-at="2025-01-13T21:21:49 IST" name="testCreateUsersWithList" finished-at="2025-01-13T21:21:50 IST" duration-ms="1198" status="PASS">
          <reporter-output>
          </reporter-output>
        </test-method> <!-- testCreateUsersWithList -->
        <test-method signature="testGetUser()[pri:4, instance:api.testcases.UserTest_Practice@233795b6]" started-at="2025-01-13T21:21:50 IST" name="testGetUser" finished-at="2025-01-13T21:21:51 IST" duration-ms="1211" status="PASS">
          <reporter-output>
          </reporter-output>
        </test-method> <!-- testGetUser -->
        <test-method signature="testGetUser_InvalidInput()[pri:5, instance:api.testcases.UserTest_Practice@233795b6]" started-at="2025-01-13T21:21:51 IST" name="testGetUser_InvalidInput" finished-at="2025-01-13T21:21:53 IST" duration-ms="1201" status="FAIL">
          <exception class="java.lang.AssertionError">
            <message>
              <![CDATA[expected [400] but found [405]]]>
            </message>
            <full-stacktrace>
              <![CDATA[java.lang.AssertionError: expected [400] but found [405]
at org.testng.Assert.fail(Assert.java:111)
at org.testng.Assert.failNotEquals(Assert.java:1578)
at org.testng.Assert.assertEqualsImpl(Assert.java:150)
at org.testng.Assert.assertEquals(Assert.java:132)
at org.testng.Assert.assertEquals(Assert.java:1419)
at org.testng.Assert.assertEquals(Assert.java:1383)
at org.testng.Assert.assertEquals(Assert.java:1429)
at api.testcases.UserTest_Practice.testGetUser_InvalidInput(UserTest_Practice.java:90)
at java.base/jdk.internal.reflect.DirectMethodHandleAccessor.invoke(DirectMethodHandleAccessor.java:103)
at java.base/java.lang.reflect.Method.invoke(Method.java:580)
at org.testng.internal.invokers.MethodInvocationHelper.invokeMethod(MethodInvocationHelper.java:141)
at org.testng.internal.invokers.TestInvoker.invokeMethod(TestInvoker.java:686)
at org.testng.internal.invokers.TestInvoker.invokeTestMethod(TestInvoker.java:230)
at org.testng.internal.invokers.MethodRunner.runInSequence(MethodRunner.java:63)
at org.testng.internal.invokers.TestInvoker$MethodInvocationAgent.invoke(TestInvoker.java:992)
at org.testng.internal.invokers.TestInvoker.invokeTestMethods(TestInvoker.java:203)
at org.testng.internal.invokers.TestMethodWorker.invokeTestMethods(TestMethodWorker.java:154)
at org.testng.internal.invokers.TestMethodWorker.run(TestMethodWorker.java:134)
at java.base/java.util.ArrayList.forEach(ArrayList.java:1597)
at org.testng.TestRunner.privateRun(TestRunner.java:739)
at org.testng.TestRunner.run(TestRunner.java:614)
at org.testng.SuiteRunner.runTest(SuiteRunner.java:421)
at org.testng.SuiteRunner.runSequentially(SuiteRunner.java:413)
at org.testng.SuiteRunner.privateRun(SuiteRunner.java:373)
at org.testng.SuiteRunner.run(SuiteRunner.java:312)
at org.testng.SuiteRunnerWorker.runSuite(SuiteRunnerWorker.java:52)
at org.testng.SuiteRunnerWorker.run(SuiteRunnerWorker.java:95)
at org.testng.TestNG.runSuitesSequentially(TestNG.java:1274)
at org.testng.TestNG.runSuitesLocally(TestNG.java:1208)
at org.testng.TestNG.runSuites(TestNG.java:1112)
at org.testng.TestNG.run(TestNG.java:1079)
at org.testng.remote.AbstractRemoteTestNG.run(AbstractRemoteTestNG.java:115)
at org.testng.remote.RemoteTestNG.initAndRun(RemoteTestNG.java:293)
at org.testng.remote.RemoteTestNG.main(RemoteTestNG.java:91)
]]>
            </full-stacktrace>
          </exception> <!-- java.lang.AssertionError -->
          <reporter-output>
          </reporter-output>
        </test-method> <!-- testGetUser_InvalidInput -->
        <test-method signature="testGetUser_NotFound()[pri:6, instance:api.testcases.UserTest_Practice@233795b6]" started-at="2025-01-13T21:21:53 IST" name="testGetUser_NotFound" finished-at="2025-01-13T21:21:54 IST" duration-ms="1190" status="PASS">
          <reporter-output>
          </reporter-output>
        </test-method> <!-- testGetUser_NotFound -->
        <test-method signature="testUpdateUser()[pri:7, instance:api.testcases.UserTest_Practice@233795b6]" started-at="2025-01-13T21:21:54 IST" name="testUpdateUser" finished-at="2025-01-13T21:21:55 IST" duration-ms="1160" status="PASS">
          <reporter-output>
          </reporter-output>
        </test-method> <!-- testUpdateUser -->
        <test-method signature="testUpdateUser_InvalidInput()[pri:8, instance:api.testcases.UserTest_Practice@233795b6]" started-at="2025-01-13T21:21:55 IST" name="testUpdateUser_InvalidInput" finished-at="2025-01-13T21:21:56 IST" duration-ms="1188" status="FAIL">
          <exception class="java.lang.AssertionError">
            <message>
              <![CDATA[expected [400] but found [200]]]>
            </message>
            <full-stacktrace>
              <![CDATA[java.lang.AssertionError: expected [400] but found [200]
at org.testng.Assert.fail(Assert.java:111)
at org.testng.Assert.failNotEquals(Assert.java:1578)
at org.testng.Assert.assertEqualsImpl(Assert.java:150)
at org.testng.Assert.assertEquals(Assert.java:132)
at org.testng.Assert.assertEquals(Assert.java:1419)
at org.testng.Assert.assertEquals(Assert.java:1383)
at org.testng.Assert.assertEquals(Assert.java:1429)
at api.testcases.UserTest_Practice.testUpdateUser_InvalidInput(UserTest_Practice.java:120)
at java.base/jdk.internal.reflect.DirectMethodHandleAccessor.invoke(DirectMethodHandleAccessor.java:103)
at java.base/java.lang.reflect.Method.invoke(Method.java:580)
at org.testng.internal.invokers.MethodInvocationHelper.invokeMethod(MethodInvocationHelper.java:141)
at org.testng.internal.invokers.TestInvoker.invokeMethod(TestInvoker.java:686)
at org.testng.internal.invokers.TestInvoker.invokeTestMethod(TestInvoker.java:230)
at org.testng.internal.invokers.MethodRunner.runInSequence(MethodRunner.java:63)
at org.testng.internal.invokers.TestInvoker$MethodInvocationAgent.invoke(TestInvoker.java:992)
at org.testng.internal.invokers.TestInvoker.invokeTestMethods(TestInvoker.java:203)
at org.testng.internal.invokers.TestMethodWorker.invokeTestMethods(TestMethodWorker.java:154)
at org.testng.internal.invokers.TestMethodWorker.run(TestMethodWorker.java:134)
at java.base/java.util.ArrayList.forEach(ArrayList.java:1597)
at org.testng.TestRunner.privateRun(TestRunner.java:739)
at org.testng.TestRunner.run(TestRunner.java:614)
at org.testng.SuiteRunner.runTest(SuiteRunner.java:421)
at org.testng.SuiteRunner.runSequentially(SuiteRunner.java:413)
at org.testng.SuiteRunner.privateRun(SuiteRunner.java:373)
at org.testng.SuiteRunner.run(SuiteRunner.java:312)
at org.testng.SuiteRunnerWorker.runSuite(SuiteRunnerWorker.java:52)
at org.testng.SuiteRunnerWorker.run(SuiteRunnerWorker.java:95)
at org.testng.TestNG.runSuitesSequentially(TestNG.java:1274)
at org.testng.TestNG.runSuitesLocally(TestNG.java:1208)
at org.testng.TestNG.runSuites(TestNG.java:1112)
at org.testng.TestNG.run(TestNG.java:1079)
at org.testng.remote.AbstractRemoteTestNG.run(AbstractRemoteTestNG.java:115)
at org.testng.remote.RemoteTestNG.initAndRun(RemoteTestNG.java:293)
at org.testng.remote.RemoteTestNG.main(RemoteTestNG.java:91)
]]>
            </full-stacktrace>
          </exception> <!-- java.lang.AssertionError -->
          <reporter-output>
          </reporter-output>
        </test-method> <!-- testUpdateUser_InvalidInput -->
        <test-method signature="testUpdateUser_NotFound()[pri:9, instance:api.testcases.UserTest_Practice@233795b6]" started-at="2025-01-13T21:21:56 IST" name="testUpdateUser_NotFound" finished-at="2025-01-13T21:21:57 IST" duration-ms="1117" status="FAIL">
          <exception class="java.lang.AssertionError">
            <message>
              <![CDATA[expected [404] but found [200]]]>
            </message>
            <full-stacktrace>
              <![CDATA[java.lang.AssertionError: expected [404] but found [200]
at org.testng.Assert.fail(Assert.java:111)
at org.testng.Assert.failNotEquals(Assert.java:1578)
at org.testng.Assert.assertEqualsImpl(Assert.java:150)
at org.testng.Assert.assertEquals(Assert.java:132)
at org.testng.Assert.assertEquals(Assert.java:1419)
at org.testng.Assert.assertEquals(Assert.java:1383)
at org.testng.Assert.assertEquals(Assert.java:1429)
at api.testcases.UserTest_Practice.testUpdateUser_NotFound(UserTest_Practice.java:129)
at java.base/jdk.internal.reflect.DirectMethodHandleAccessor.invoke(DirectMethodHandleAccessor.java:103)
at java.base/java.lang.reflect.Method.invoke(Method.java:580)
at org.testng.internal.invokers.MethodInvocationHelper.invokeMethod(MethodInvocationHelper.java:141)
at org.testng.internal.invokers.TestInvoker.invokeMethod(TestInvoker.java:686)
at org.testng.internal.invokers.TestInvoker.invokeTestMethod(TestInvoker.java:230)
at org.testng.internal.invokers.MethodRunner.runInSequence(MethodRunner.java:63)
at org.testng.internal.invokers.TestInvoker$MethodInvocationAgent.invoke(TestInvoker.java:992)
at org.testng.internal.invokers.TestInvoker.invokeTestMethods(TestInvoker.java:203)
at org.testng.internal.invokers.TestMethodWorker.invokeTestMethods(TestMethodWorker.java:154)
at org.testng.internal.invokers.TestMethodWorker.run(TestMethodWorker.java:134)
at java.base/java.util.ArrayList.forEach(ArrayList.java:1597)
at org.testng.TestRunner.privateRun(TestRunner.java:739)
at org.testng.TestRunner.run(TestRunner.java:614)
at org.testng.SuiteRunner.runTest(SuiteRunner.java:421)
at org.testng.SuiteRunner.runSequentially(SuiteRunner.java:413)
at org.testng.SuiteRunner.privateRun(SuiteRunner.java:373)
at org.testng.SuiteRunner.run(SuiteRunner.java:312)
at org.testng.SuiteRunnerWorker.runSuite(SuiteRunnerWorker.java:52)
at org.testng.SuiteRunnerWorker.run(SuiteRunnerWorker.java:95)
at org.testng.TestNG.runSuitesSequentially(TestNG.java:1274)
at org.testng.TestNG.runSuitesLocally(TestNG.java:1208)
at org.testng.TestNG.runSuites(TestNG.java:1112)
at org.testng.TestNG.run(TestNG.java:1079)
at org.testng.remote.AbstractRemoteTestNG.run(AbstractRemoteTestNG.java:115)
at org.testng.remote.RemoteTestNG.initAndRun(RemoteTestNG.java:293)
at org.testng.remote.RemoteTestNG.main(RemoteTestNG.java:91)
]]>
            </full-stacktrace>
          </exception> <!-- java.lang.AssertionError -->
          <reporter-output>
          </reporter-output>
        </test-method> <!-- testUpdateUser_NotFound -->
        <test-method signature="testDeleteUser()[pri:10, instance:api.testcases.UserTest_Practice@233795b6]" started-at="2025-01-13T21:21:57 IST" name="testDeleteUser" finished-at="2025-01-13T21:21:58 IST" duration-ms="1122" status="PASS">
          <reporter-output>
          </reporter-output>
        </test-method> <!-- testDeleteUser -->
        <test-method signature="testDeleteUser_InvalidInput()[pri:11, instance:api.testcases.UserTest_Practice@233795b6]" started-at="2025-01-13T21:21:58 IST" name="testDeleteUser_InvalidInput" finished-at="2025-01-13T21:22:00 IST" duration-ms="1114" status="FAIL">
          <exception class="java.lang.AssertionError">
            <message>
              <![CDATA[expected [400] but found [404]]]>
            </message>
            <full-stacktrace>
              <![CDATA[java.lang.AssertionError: expected [400] but found [404]
at org.testng.Assert.fail(Assert.java:111)
at org.testng.Assert.failNotEquals(Assert.java:1578)
at org.testng.Assert.assertEqualsImpl(Assert.java:150)
at org.testng.Assert.assertEquals(Assert.java:132)
at org.testng.Assert.assertEquals(Assert.java:1419)
at org.testng.Assert.assertEquals(Assert.java:1383)
at org.testng.Assert.assertEquals(Assert.java:1429)
at api.testcases.UserTest_Practice.testDeleteUser_InvalidInput(UserTest_Practice.java:147)
at java.base/jdk.internal.reflect.DirectMethodHandleAccessor.invoke(DirectMethodHandleAccessor.java:103)
at java.base/java.lang.reflect.Method.invoke(Method.java:580)
at org.testng.internal.invokers.MethodInvocationHelper.invokeMethod(MethodInvocationHelper.java:141)
at org.testng.internal.invokers.TestInvoker.invokeMethod(TestInvoker.java:686)
at org.testng.internal.invokers.TestInvoker.invokeTestMethod(TestInvoker.java:230)
at org.testng.internal.invokers.MethodRunner.runInSequence(MethodRunner.java:63)
at org.testng.internal.invokers.TestInvoker$MethodInvocationAgent.invoke(TestInvoker.java:992)
at org.testng.internal.invokers.TestInvoker.invokeTestMethods(TestInvoker.java:203)
at org.testng.internal.invokers.TestMethodWorker.invokeTestMethods(TestMethodWorker.java:154)
at org.testng.internal.invokers.TestMethodWorker.run(TestMethodWorker.java:134)
at java.base/java.util.ArrayList.forEach(ArrayList.java:1597)
at org.testng.TestRunner.privateRun(TestRunner.java:739)
at org.testng.TestRunner.run(TestRunner.java:614)
at org.testng.SuiteRunner.runTest(SuiteRunner.java:421)
at org.testng.SuiteRunner.runSequentially(SuiteRunner.java:413)
at org.testng.SuiteRunner.privateRun(SuiteRunner.java:373)
at org.testng.SuiteRunner.run(SuiteRunner.java:312)
at org.testng.SuiteRunnerWorker.runSuite(SuiteRunnerWorker.java:52)
at org.testng.SuiteRunnerWorker.run(SuiteRunnerWorker.java:95)
at org.testng.TestNG.runSuitesSequentially(TestNG.java:1274)
at org.testng.TestNG.runSuitesLocally(TestNG.java:1208)
at org.testng.TestNG.runSuites(TestNG.java:1112)
at org.testng.TestNG.run(TestNG.java:1079)
at org.testng.remote.AbstractRemoteTestNG.run(AbstractRemoteTestNG.java:115)
at org.testng.remote.RemoteTestNG.initAndRun(RemoteTestNG.java:293)
at org.testng.remote.RemoteTestNG.main(RemoteTestNG.java:91)
]]>
            </full-stacktrace>
          </exception> <!-- java.lang.AssertionError -->
          <reporter-output>
          </reporter-output>
        </test-method> <!-- testDeleteUser_InvalidInput -->
        <test-method signature="testDeleteUser_NotFound()[pri:12, instance:api.testcases.UserTest_Practice@233795b6]" started-at="2025-01-13T21:22:00 IST" name="testDeleteUser_NotFound" finished-at="2025-01-13T21:22:01 IST" duration-ms="1096" status="PASS">
          <reporter-output>
          </reporter-output>
        </test-method> <!-- testDeleteUser_NotFound -->
        <test-method signature="testLoginUser()[pri:13, instance:api.testcases.UserTest_Practice@233795b6]" started-at="2025-01-13T21:22:01 IST" name="testLoginUser" finished-at="2025-01-13T21:22:02 IST" duration-ms="1248" status="PASS">
          <reporter-output>
          </reporter-output>
        </test-method> <!-- testLoginUser -->
        <test-method signature="testLogoutUser()[pri:14, instance:api.testcases.UserTest_Practice@233795b6]" started-at="2025-01-13T21:22:02 IST" name="testLogoutUser" finished-at="2025-01-13T21:22:03 IST" duration-ms="1107" status="PASS">
          <reporter-output>
          </reporter-output>
        </test-method> <!-- testLogoutUser -->
      </class> <!-- api.testcases.UserTest_Practice -->
    </test> <!-- Default test -->
  </suite> <!-- Default suite -->
</testng-results>
